Workbook

Sheet 銲接型式
A1: 銲接型式 | B1: 說明 | C1: 加成係數 | D1: 加成係數.1
A2: BW | B2: 對銲 | C2: 1 | D2: 1
A3: SW | B3: 套銲 | C3: 1 | D3: 1
A4: FSW | B4: 套銲法蘭 | C4: 1.5 | D4: 1
A5: IW | B5: 插銲(SOCKOLET,WELDOLET,THREADOLET) | C5: 1.5 | D5: 1
A6: IWN | B6: 插銲(無補強板) | C6: 2 | D6: 1
A7: IWR | B7: 插銲(有補強板) | C7: 4 | D7: 1.5
A8: NPT | B8: 牙口 | C8: 1 | D8: 1
A9: FF | C9: 1 | D9: 1
A10: FF-CV | C10: 1.5 | D10: 1
A11: FF-SV | C11: 1.5 | D11: 1
A12: FF 或 RF | B12: 屬於安裝工作 | D12: 1
A14: 焊口編號+以下 | B14: 說明 | C14: 加成係數
A15: F | B15: 法蘭安裝 | C15: 1 | D15: 1
A16: V | B16: 閥安裝(手動閥、過濾器、軟管、眼鏡盲板、限流板等) | C16: 1 | D16: 1
A17: CV | B17: 控制閥及流量計等安裝 | C17: 1.5 | D17: 1
A18: SV | B18: 安全閥安裝 | C18: 1.5 | D18: 1
A19: V V | B19: 特殊閥安裝(如桶底閥、三通閥等等) | C19: 2 | D19: 1
A21: 銲口編號補充: | B21: 1.新增銲口:用最接近焊口+英文字母 a1..a2..a3..等依此類推
B22: 2.修改銲口:用該焊口+英文字母 r1..r2..r3..等依此類推
B23: 3.法蘭安裝銲口自行編列並加F以方便統計

Sheet DRAWING LIST
A1: Series NO | B1: DWG NO | C1: SH'T NO | D1: LINE NUMBER | E1: REV.A | F1: REV.0 | G1: REV.1 | H1: REV.2 | I1: REV.3 | J1: 最終版版次 | K1: 最終版日期 | L1: 針對PDF格式 | M1: 圖面狀態
A2: 1 | B2: (UG)FO-90401-6"-S1P1FU-01 | C2: 1/2 | D2: (UG)FO-90401-6"-S1P1FU | E2: 45702 | F2: 45747 | G2: 45765 | H2: 45789 | I2: 45856 | J2: {=INDEX(E$1:I$1,1,MATCH(1,1/($E2:I2<>"")))} -> REV.3 | K2: {=TEXT(LOOKUP(2,1/($E2:I2<>""),$E2:I2),"yyyy/mm/dd")} -> 2025/07/18 | M2: 啟用
A3: 1-1 | B3: (UG)FO-90401-6"-S1P1FU-02 | C3: 2/2 | D3: (UG)FO-90401-6"-S1P1FU | I3: 45856 | J3: {=INDEX(E$1:I$1,1,MATCH(1,1/($E3:I3<>"")))} -> REV.3 | K3: {=TEXT(LOOKUP(2,1/($E3:I3<>""),$E3:I3),"yyyy/mm/dd")} -> 2025/07/18
A4: =A2+1 -> 2 | B4: (UG)FO-90401.-6"-S1P1FU-01 | C4: 1/2 | D4: (UG)FO-90401.-6"-S1P1FU | E4: 45702 | F4: 45747 | G4: 45789 | H4: 45856 | J4: {=INDEX(E$1:I$1,1,MATCH(1,1/($E4:I4<>"")))} -> REV.2 | K4: {=TEXT(LOOKUP(2,1/($E4:I4<>""),$E4:I4),"yyyy/mm/dd")} -> 2025/07/18 | M4: 啟用
A5: =A4+1 -> 3 | B5: (UG)FO-90401.-6"-S1P1FU-02 | C5: 2/2 | D5: (UG)FO-90401.-6"-S1P1FU | E5: 45702 | F5: 45747 | G5: 45789 | H5: 45856 | J5: {=INDEX(E$1:I$1,1,MATCH(1,1/($E5:I5<>"")))} -> REV.2 | K5: {=TEXT(LOOKUP(2,1/($E5:I5<>""),$E5:I5),"yyyy/mm/dd")} -> 2025/07/18 | M5: 啟用
A6: =A5+1 -> 4 | B6: (UG)FW-90201-6"-C1AU-01 | C6: 1/1 | D6: (UG)FW-90201-6"-C1AU | E6: 45702 | F6: 45747 | G6: 45789 | J6: {=INDEX(E$1:I$1,1,MATCH(1,1/($E6:I6<>"")))} -> REV.1 | K6: {=TEXT(LOOKUP(2,1/($E6:I6<>""),$E6:I6),"yyyy/mm/dd")} -> 2025/05/12 | M6: 啟用
A7: =A6+1 -> 5 | B7: (UG)FW-90201.-8"-C1AU-01 | C7: 1/3 | D7: (UG)FW-90201.-8"-C1AU | E7: 45702 | F7: 45747 | G7: 45789 | J7: {=INDEX(E$1:I$1,1,MATCH(1,1/($E7:I7<>"")))} -> REV.1 | K7: {=TEXT(LOOKUP(2,1/($E7:I7<>""),$E7:I7),"yyyy/mm/dd")} -> 2025/05/12 | M7: 啟用
A8: =A7+1 -> 6 | B8: (UG)FW-90201.-8"-C1AU-02 | C8: 2/3 | D8: (UG)FW-90201.-8"-C1AU | E8: 45702 | F8: 45747 | G8: 45789 | J8: {=INDEX(E$1:I$1,1,MATCH(1,1/($E8:I8<>"")))} -> REV.1 | K8: {=TEXT(LOOKUP(2,1/($E8:I8<>""),$E8:I8),"yyyy/mm/dd")} -> 2025/05/12 | M8: 啟用
A9: =A8+1 -> 7 | B9: (UG)FW-90201.-8"-C1AU-03 | C9: 3/3 | D9: (UG)FW-90201.-8"-C1AU | E9: 45702 | F9: 45747 | G9: 45789 | J9: {=INDEX(E$1:I$1,1,MATCH(1,1/($E9:I9<>"")))} -> REV.1 | K9: {=TEXT(LOOKUP(2,1/($E9:I9<>""),$E9:I9),"yyyy/mm/dd")} -> 2025/05/12 | M9: 啟用
A10: =A9+1 -> 8 | B10: (UG)FW-90201..-6"-C1AU-01 | C10: 1/2 | D10: (UG)FW-90201..-6"-C1AU | E10: 45702 | F10: 45747 | G10: 45789 | J10: {=INDEX(E$1:I$1,1,MATCH(1,1/($E10:I10<>"")))} -> REV.1 | K10: {=TEXT(LOOKUP(2,1/($E10:I10<>""),$E10:I10),"yyyy/mm/dd")} -> 2025/05/12 | M10: 啟用
A11: =A10+1 -> 9 | B11: (UG)FW-90201..-6"-C1AU-02 | C11: 2/2 | D11: (UG)FW-90201..-6"-C1AU | E11: 45702 | F11: 45747 | G11: 45789 | J11: {=INDEX(E$1:I$1,1,MATCH(1,1/($E11:I11<>"")))} -> REV.1 | K11: {=TEXT(LOOKUP(2,1/($E11:I11<>""),$E11:I11),"yyyy/mm/dd")} -> 2025/05/12 | M11: 啟用
A12: =A11+1 -> 10 | B12: (UG)FW-90201...-6"-C1AU-01 | C12: 1/2 | D12: (UG)FW-90201...-6"-C1AU | E12: 45702 | F12: 45747 | G12: 45789 | J12: {=INDEX(E$1:I$1,1,MATCH(1,1/($E12:I12<>"")))} -> REV.1 | K12: {=TEXT(LOOKUP(2,1/($E12:I12<>""),$E12:I12),"yyyy/mm/dd")} -> 2025/05/12 | M12: 啟用
A13: =A12+1 -> 11 | B13: (UG)FW-90201...-6"-C1AU-02 | C13: 2/2 | D13: (UG)FW-90201...-6"-C1AU | E13: 45702 | F13: 45747 | G13: 45789 | J13: {=INDEX(E$1:I$1,1,MATCH(1,1/($E13:I13<>"")))} -> REV.1 | K13: {=TEXT(LOOKUP(2,1/($E13:I13<>""),$E13:I13),"yyyy/mm/dd")} -> 2025/05/12 | M13: 啟用
A14: =A13+1 -> 12 | B14: (UG)FW-90202-6"-C1AU-01 | C14: 1/1 | D14: (UG)FW-90202-6"-C1AU | E14: 45702 | F14: 45747 | G14: 45789 | J14: {=INDEX(E$1:I$1,1,MATCH(1,1/($E14:I14<>"")))} -> REV.1 | K14: {=TEXT(LOOKUP(2,1/($E14:I14<>""),$E14:I14),"yyyy/mm/dd")} -> 2025/05/12 | M14: 啟用
A15: =A14+1 -> 13 | B15: (UG)IW-11001-4"-C1AU-01 | C15: 1/1 | D15: (UG)IW-11001-4"-C1AU | E15: 45702 | F15: 45747 | G15: 45765 | H15: 45789 | J15: {=INDEX(E$1:I$1,1,MATCH(1,1/($E15:I15<>"")))} -> REV.2 | K15: {=TEXT(LOOKUP(2,1/($E15:I15<>""),$E15:I15),"yyyy/mm/dd")} -> 2025/05/12 | M15: 啟用
A16: =A15+1 -> 14 | B16: (UG)SW-11201-4"-S1P4U-01 | C16: 1/1 | D16: (UG)SW-11201-4"-S1P4U | E16: 45702 | F16: 45747 | G16: 45765 | H16: 45789 | J16: {=INDEX(E$1:I$1,1,MATCH(1,1/($E16:I16<>"")))} -> REV.2 | K16: {=TEXT(LOOKUP(2,1/($E16:I16<>""),$E16:I16),"yyyy/mm/dd")} -> 2025/05/12 | M16: 啟用
A17: =A16+1 -> 15 | B17: (UG)TRIM-W1808-N6-4"-S1P4U-01 | C17: 1/1 | D17: (UG)TRIM-W1808-N6-4"-S1P4U | F17: 45747 | J17: {=INDEX(E$1:I$1,1,MATCH(1,1/($E17:I17<>"")))} -> REV.0 | K17: {=TEXT(LOOKUP(2,1/($E17:I17<>""),$E17:I17),"yyyy/mm/dd")} -> 2025/03/31 | M17: 啟用
A18: =A17+1 -> 16 | B18: (UG)WW-12101-4"-S1P4U-01 | C18: 1/2 | D18: (UG)WW-12101-4"-S1P4U | E18: 45702 | F18: 45747 | G18: 45765 | H18: 45789 | J18: {=INDEX(E$1:I$1,1,MATCH(1,1/($E18:I18<>"")))} -> REV.2 | K18: {=TEXT(LOOKUP(2,1/($E18:I18<>""),$E18:I18),"yyyy/mm/dd")} -> 2025/05/12 | M18: 啟用
A19: =A18+1 -> 17 | B19: (UG)WW-12101-4"-S1P4U-02 | C19: 2/2 | D19: (UG)WW-12101-4"-S1P4U | E19: 45702 | F19: 45747 | G19: 45765 | H19: 45789 | J19: {=INDEX(E$1:I$1,1,MATCH(1,1/($E19:I19<>"")))} -> REV.2 | K19: {=TEXT(LOOKUP(2,1/($E19:I19<>""),$E19:I19),"yyyy/mm/dd")} -> 2025/05/12 | M19: 啟用
A20: =A19+1 -> 18 | B20: (UG)WW-18011-4"-S1P4U-01 | C20: 1/1 | D20: (UG)WW-18011-4"-S1P4U | E20: 45702 | F20: 45747 | J20: {=INDEX(E$1:I$1,1,MATCH(1,1/($E20:I20<>"")))} -> REV.0 | K20: {=TEXT(LOOKUP(2,1/($E20:I20<>""),$E20:I20),"yyyy/mm/dd")} -> 2025/03/31 | M20: 啟用
A21: =A20+1 -> 19 | B21: (UG)WW-18015-4"-S1P4U-01 | C21: 1/1 | D21: (UG)WW-18015-4"-S1P4U | E21: 45702 | F21: 45747 | G21: 45765 | H21: 45789 | J21: {=INDEX(E$1:I$1,1,MATCH(1,1/($E21:I21<>"")))} -> REV.2 | K21: {=TEXT(LOOKUP(2,1/($E21:I21<>""),$E21:I21),"yyyy/mm/dd")} -> 2025/05/12 | M21: 啟用
A22: =A21+1 -> 20 | B22: (UG)WW-18016-4"-S1P4U-01 | C22: 1/1 | D22: (UG)WW-18016-4"-S1P4U | E22: 45702 | F22: 45747 | G22: 45765 | H22: 45789 | J22: {=INDEX(E$1:I$1,1,MATCH(1,1/($E22:I22<>"")))} -> REV.2 | K22: {=TEXT(LOOKUP(2,1/($E22:I22<>""),$E22:I22),"yyyy/mm/dd")} -> 2025/05/12 | M22: 啟用
A23: =A22+1 -> 21 | B23: (UG)WW-18017-3"-S1P4U-01 | C23: 1/1 | D23: (UG)WW-18017-3"-S1P4U | E23: 45702 | F23: 45747 | J23: {=INDEX(E$1:I$1,1,MATCH(1,1/($E23:I23<>"")))} -> REV.0 | K23: {=TEXT(LOOKUP(2,1/($E23:I23<>""),$E23:I23),"yyyy/mm/dd")} -> 2025/03/31 | M23: 啟用
A24: =A23+1 -> 22 | B24: (UG)WW-18021-8"-S1P4U-01 | C24: 1/1 | D24: (UG)WW-18021-8"-S1P4U | E24: 45702 | F24: 45747 | J24: {=INDEX(E$1:I$1,1,MATCH(1,1/($E24:I24<>"")))} -> REV.0 | K24: {=TEXT(LOOKUP(2,1/($E24:I24<>""),$E24:I24),"yyyy/mm/dd")} -> 2025/03/31 | M24: 啟用
A25: =A24+1 -> 23 | B25: (UG)WW-18022-6"-S1P4U-01 | C25: 1/1 | D25: (UG)WW-18022-6"-S1P4U | E25: 45702 | F25: 45747 | J25: {=INDEX(E$1:I$1,1,MATCH(1,1/($E25:I25<>"")))} -> REV.0 | K25: {=TEXT(LOOKUP(2,1/($E25:I25<>""),$E25:I25),"yyyy/mm/dd")} -> 2025/03/31 | M25: 啟用
A26: =A25+1 -> 24 | B26: (UG)WW-18023-4"-S1P4U-01 | C26: 1/1 | D26: (UG)WW-18023-4"-S1P4U | E26: 45702 | F26: 45747 | J26: {=INDEX(E$1:I$1,1,MATCH(1,1/($E26:I26<>"")))} -> REV.0 | K26: {=TEXT(LOOKUP(2,1/($E26:I26<>""),$E26:I26),"yyyy/mm/dd")} -> 2025/03/31 | M26: 啟用
A27: =A26+1 -> 25 | B27: (UG)WW-18026-6"-S1P4U-01 | C27: 1/1 | D27: (UG)WW-18026-6"-S1P4U | E27: 45702 | F27: 45747 | J27: {=INDEX(E$1:I$1,1,MATCH(1,1/($E27:I27<>"")))} -> REV.0 | K27: {=TEXT(LOOKUP(2,1/($E27:I27<>""),$E27:I27),"yyyy/mm/dd")} -> 2025/03/31 | M27: 啟用
A28: =A27+1 -> 26 | B28: (UG)WW-18031-6"-S1P4U-01 | C28: 1/1 | D28: (UG)WW-18031-6"-S1P4U | E28: 45702 | F28: 45747 | J28: {=INDEX(E$1:I$1,1,MATCH(1,1/($E28:I28<>"")))} -> REV.0 | K28: {=TEXT(LOOKUP(2,1/($E28:I28<>""),$E28:I28),"yyyy/mm/dd")} -> 2025/03/31 | M28: 啟用
A29: =A28+1 -> 27 | B29: (UG)WW-18032-4"-S1P4U-01 | C29: 1/1 | D29: (UG)WW-18032-4"-S1P4U | E29: 45702 | F29: 45747 | J29: {=INDEX(E$1:I$1,1,MATCH(1,1/($E29:I29<>"")))} -> REV.0 | K29: {=TEXT(LOOKUP(2,1/($E29:I29<>""),$E29:I29),"yyyy/mm/dd")} -> 2025/03/31 | M29: 啟用
A30: =A29+1 -> 28 | B30: (UG)WW-18033-4"-S1P4U-01 | C30: 1/1 | D30: (UG)WW-18033-4"-S1P4U | E30: 45702 | F30: 45747 | J30: {=INDEX(E$1:I$1,1,MATCH(1,1/($E30:I30<>"")))} -> REV.0 | K30: {=TEXT(LOOKUP(2,1/($E30:I30<>""),$E30:I30),"yyyy/mm/dd")} -> 2025/03/31 | M30: 啟用
A31: =A30+1 -> 29 | B31: (UG)WW-18039-4"-S1P4U-01 | C31: 1/1 | D31: (UG)WW-18039-4"-S1P4U | E31: 45702 | F31: 45747 | J31: {=INDEX(E$1:I$1,1,MATCH(1,1/($E31:I31<>"")))} -> REV.0 | K31: {=TEXT(LOOKUP(2,1/($E31:I31<>""),$E31:I31),"yyyy/mm/dd")} -> 2025/03/31 | M31: 啟用
A32: =A31+1 -> 30 | B32: (UG)WW-18041-2"-S1P4U-01 | C32: 1/2 | D32: (UG)WW-18041-2"-S1P4U | E32: 45702 | F32: 45747 | G32: 45765 | H32: 45789 | J32: {=INDEX(E$1:I$1,1,MATCH(1,1/($E32:I32<>"")))} -> REV.2 | K32: {=TEXT(LOOKUP(2,1/($E32:I32<>""),$E32:I32),"yyyy/mm/dd")} -> 2025/05/12 | M32: 啟用
A33: =A32+1 -> 31 | B33: (UG)WW-18041-2"-S1P4U-02 | C33: 2/2 | D33: (UG)WW-18041-2"-S1P4U | E33: 45702 | F33: 45747 | G33: 45765 | H33: 45789 | J33: {=INDEX(E$1:I$1,1,MATCH(1,1/($E33:I33<>"")))} -> REV.2 | K33: {=TEXT(LOOKUP(2,1/($E33:I33<>""),$E33:I33),"yyyy/mm/dd")} -> 2025/05/12 | M33: 啟用
A34: =A33+1 -> 32 | B34: (UG)WW-18042-2"-S1P4U-01 | C34: 1/1 | D34: (UG)WW-18042-2"-S1P4U | E34: 45702 | F34: 45747 | J34: {=INDEX(E$1:I$1,1,MATCH(1,1/($E34:I34<>"")))} -> REV.0 | K34: {=TEXT(LOOKUP(2,1/($E34:I34<>""),$E34:I34),"yyyy/mm/dd")} -> 2025/03/31 | M34: 啟用
A35: =A34+1 -> 33 | B35: (UG)WW-18044-4"-S1P4U-01 | C35: 1/1 | D35: (UG)WW-18044-4"-S1P4U | E35: 45702 | F35: 45747 | J35: {=INDEX(E$1:I$1,1,MATCH(1,1/($E35:I35<>"")))} -> REV.0 | K35: {=TEXT(LOOKUP(2,1/($E35:I35<>""),$E35:I35),"yyyy/mm/dd")} -> 2025/03/31 | M35: 啟用
A36: =A35+1 -> 34 | B36: (UG)WW-18048-2"-S1P4U-01 | C36: 1/1 | D36: (UG)WW-18048-2"-S1P4U | E36: 45702 | F36: 45747 | G36: 45765 | H36: 45789 | J36: {=INDEX(E$1:I$1,1,MATCH(1,1/($E36:I36<>"")))} -> REV.2 | K36: {=TEXT(LOOKUP(2,1/($E36:I36<>""),$E36:I36),"yyyy/mm/dd")} -> 2025/05/12 | M36: 啟用
A37: =A36+1 -> 35 | B37: (UG)WW-18052-8"-S1P4U-01 | C37: 1/1 | D37: (UG)WW-18052-8"-S1P4U | E37: 45702 | F37: 45747 | J37: {=INDEX(E$1:I$1,1,MATCH(1,1/($E37:I37<>"")))} -> REV.0 | K37: {=TEXT(LOOKUP(2,1/($E37:I37<>""),$E37:I37),"yyyy/mm/dd")} -> 2025/03/31 | M37: 啟用
A38: =A37+1 -> 36 | B38: (UG)WW-18091-3"-S1P4U-01 | C38: 1/1 | D38: (UG)WW-18091-3"-S1P4U | E38: 45702 | F38: 45747 | G38: 45789 | H38: 45797 | J38: {=INDEX(E$1:I$1,1,MATCH(1,1/($E38:I38<>"")))} -> REV.2 | K38: {=TEXT(LOOKUP(2,1/($E38:I38<>""),$E38:I38),"yyyy/mm/dd")} -> 2025/05/20 | M38: 啟用
A39: =A38+1 -> 37 | B39: (UG)WW-18092-6"-S1P4U-01 | C39: 1/1 | D39: (UG)WW-18092-6"-S1P4U | E39: 45702 | F39: 45747 | G39: 45765 | H39: 45789 | J39: {=INDEX(E$1:I$1,1,MATCH(1,1/($E39:I39<>"")))} -> REV.2 | K39: {=TEXT(LOOKUP(2,1/($E39:I39<>""),$E39:I39),"yyyy/mm/dd")} -> 2025/05/12 | M39: 啟用
A40: =A39+1 -> 38 | B40: (UG)WW-19021-4"-S1P4U-01 | C40: 1/1 | D40: (UG)WW-19021-4"-S1P4U | E40: 45702 | F40: 45747 | J40: {=INDEX(E$1:I$1,1,MATCH(1,1/($E40:I40<>"")))} -> REV.0 | K40: {=TEXT(LOOKUP(2,1/($E40:I40<>""),$E40:I40),"yyyy/mm/dd")} -> 2025/03/31 | M40: 關閉
...

Sheet 分析
A1: SE-37-焊口管制表-114.07.21
D3: 值
A4: 材質 | B4: 銲接型式 | C4: 尺寸 | D4: 計數 - 銲口編號 | E4: 加總 - DB數
A5: 304 | B5: BW | C5: 1 | D5: 6 | E5: 6
C6: 2 | D6: 52 | E6: 104
C7: 3 | D7: 31 | E7: 93
C8: 4 | D8: 117 | E8: 468
C9: 8 | D9: 11 | E9: 88
C10: 6 | D10: 67 | E10: 402
B11: IW | C11: 1.5 | D11: 2 | E11: 3
B12: SW | C12: 1 | D12: 12 | E12: 12
C13: 1.5 | D13: 6 | E13: 9
B14: FF | C14: 2 | D14: 6 | E14: 12
C15: 3 | D15: 2 | E15: 6
C16: 4 | D16: 6 | E16: 24
C17: 8 | D17: 2 | E17: 16
C18: 6 | D18: 4 | E18: 24
B19: T | C19: 1.5 | D19: 2 | E19: 3
A20: 304 合計 | D20: 326 | E20: 1270
A21: GALV | B21: BW | C21: 2.5 | D21: 22 | E21: 55
C22: 4 | D22: 14 | E22: 56
C23: 8 | D23: 8 | E23: 64
C24: 6 | D24: 79 | E24: 474
B25: IW | C25: 0.5 | D25: 3 | E25: 3
C26: 2.5 | D26: 1 | E26: 2.5
B27: SW | C27: 0.5 | D27: 6 | E27: 6
B28: FF | C28: 2.5 | D28: 6 | E28: 15
C29: 6 | D29: 6 | E29: 36
A30: GALV 合計 | D30: 145 | E30: 711.5
A31: (空白) | B31: (空白) | C31: (空白)
A32: (空白) 合計
A33: 總計 | D33: 471 | E33: 1981.5

Sheet 分析-114.05.21預製完成
A1: 分析-114.05.21預製完成
E4: 組銲完成日期 | F4: 值
A6: 材質 | B6: 尺寸 | C6: 厚度 | D6: 品項 | E6: 計數 - 銲口編號 | F6: 加總 - DB數
A7: 304 | B7: 1 | C7: S-40 | D7: (空白) | E7: 4 | F7: 4
B8: 2 | C8: S-40 | D8: (空白) | E8: 13 | F8: 26
B9: 3 | C9: S-40 | D9: (空白) | E9: 7 | F9: 21
B10: 4 | C10: S-10 | D10: (空白) | E10: 2 | F10: 8
C11: S-40 | D11: (空白) | E11: 12 | F11: 48
B12: 8 | C12: S-40 | D12: (空白) | E12: 2 | F12: 16
B13: 6 | C13: S-10 | D13: (空白) | E13: 1 | F13: 6
C14: S-40 | D14: (空白) | E14: 4 | F14: 24
B15: 1.5 | C15: S-40 | D15: (空白) | E15: 1 | F15: 1.5
A16: 304 合計 | E16: 46 | F16: 154.5
A17: GALV | B17: 2.5 | C17: S-40 | D17: (空白) | E17: 6 | F17: 15
C18: S-80 | D18: (空白) | E18: 1 | F18: 2.5
B19: 6 | C19: S-40 | D19: (空白) | E19: 12 | F19: 72
A20: GALV 合計 | E20: 19 | F20: 89.5
A21: 總計 | E21: 65 | F21: 244

Sheet 焊口編號明細
A1: 流水號 | B1: DWG NO | C1: SHEET NO | D1: 銲口編號 | E1: 尺寸 | F1: DB數 | G1: 厚度 | H1: 材質 | I1: 銲接型式 | J1: 預製S/ 現場F | K1: 組銲完成日期 | L1: RT.PT檢驗焊口 | M1: RT.PT檢驗日期 | N1: 品項 | O1: 備註 | P1: Line_num | Q1: hyper | R1: NOTE | S1: 計數
A2: 1 | B2: (UG)FO-90401-S1P1FU-01 | C2: 1/2 | D2: 1 | E2: 6 | F2: =IF(E2<>"",IF(Weld_list[[#This Row],[尺寸]]<1,1,E2),"") -> 6 | G2: S-10 | H2: 304 | I2: BW | J2: S | K2: =IFERROR(TEXT(_xlfn.XLOOKUP(_xlfn.CONCAT(Weld_list[[#This Row],[流水號]],"_",Weld_list[[#This Row],[銲口編號]]),焊口登報表!D:D,焊口登報表!C:C,,0),"yyyy/mm/dd"),"") -> 2025/08/25 | L2: VV | M2: 45897 | Q2: =HYPERLINK(_xlfn.CONCAT("\\192.168.1.50\3勝一\SE-37(彰濱)\01.工程圖面\01.ISO\ISO\",Weld_list[[#This Row],[流水號]],".",Weld_list[[#This Row],[DWG NO]],".pdf")) -> \\192.168.1.50\3勝一\SE-37(彰濱)\01.工程圖面\01.ISO\ISO\1.(UG)FO-90401-S1P1FU-01.pdf | R2: =IF(Weld_list[[#This Row],[組銲完成日期]]<>"","已完成","未完成") -> 已完成 | S2: 1
A3: 1 | B3: (UG)FO-90401-S1P1FU-01 | C3: 1/2 | D3: 2 | E3: 6 | F3: =IF(E3<>"",IF(Weld_list[[#This Row],[尺寸]]<1,1,E3),"") -> 6 | G3: S-10 | H3: 304 | I3: BW | J3: S | K3: =IFERROR(TEXT(_xlfn.XLOOKUP(_xlfn.CONCAT(Weld_list[[#This Row],[流水號]],"_",Weld_list[[#This Row],[銲口編號]]),焊口登報表!D:D,焊口登報表!C:C,,0),"yyyy/mm/dd"),"") -> 2025/08/25 | L3: VV | M3: 45897 | Q3: =HYPERLINK(_xlfn.CONCAT("\\192.168.1.50\3勝一\SE-37(彰濱)\01.工程圖面\01.ISO\ISO\",Weld_list[[#This Row],[流水號]],".",Weld_list[[#This Row],[DWG NO]],".pdf")) -> \\192.168.1.50\3勝一\SE-37(彰濱)\01.工程圖面\01.ISO\ISO\1.(UG)FO-90401-S1P1FU-01.pdf | R3: =IF(Weld_list[[#This Row],[組銲完成日期]]<>"","已完成","未完成") -> 已完成 | S3: 1
A4: 1 | B4: (UG)FO-90401-S1P1FU-01 | C4: 1/2 | D4: 3 | E4: 6 | F4: =IF(E4<>"",IF(Weld_list[[#This Row],[尺寸]]<1,1,E4),"") -> 6 | G4: S-10 | H4: 304 | I4: BW | J4: S | K4: =IFERROR(TEXT(_xlfn.XLOOKUP(_xlfn.CONCAT(Weld_list[[#This Row],[流水號]],"_",Weld_list[[#This Row],[銲口編號]]),焊口登報表!D:D,焊口登報表!C:C,,0),"yyyy/mm/dd"),"") -> 2025/08/25 | L4: VV | M4: 45897 | Q4: =HYPERLINK(_xlfn.CONCAT("\\192.168.1.50\3勝一\SE-37(彰濱)\01.工程圖面\01.ISO\ISO\",Weld_list[[#This Row],[流水號]],".",Weld_list[[#This Row],[DWG NO]],".pdf")) -> \\192.168.1.50\3勝一\SE-37(彰濱)\01.工程圖面\01.ISO\ISO\1.(UG)FO-90401-S1P1FU-01.pdf | R4: =IF(Weld_list[[#This Row],[組銲完成日期]]<>"","已完成","未完成") -> 已完成 | S4: 1
A5: 1 | B5: (UG)FO-90401-S1P1FU-01 | C5: 1/2 | D5: 4 | E5: 6 | F5: =IF(E5<>"",IF(Weld_list[[#This Row],[尺寸]]<1,1,E5),"") -> 6 | G5: S-10 | H5: 304 | I5: BW | J5: S | K5: =IFERROR(TEXT(_xlfn.XLOOKUP(_xlfn.CONCAT(Weld_list[[#This Row],[流水號]],"_",Weld_list[[#This Row],[銲口編號]]),焊口登報表!D:D,焊口登報表!C:C,,0),"yyyy/mm/dd"),"") -> 2025/08/25 | L5: VV | M5: 45897 | Q5: =HYPERLINK(_xlfn.CONCAT("\\192.168.1.50\3勝一\SE-37(彰濱)\01.工程圖面\01.ISO\ISO\",Weld_list[[#This Row],[流水號]],".",Weld_list[[#This Row],[DWG NO]],".pdf")) -> \\192.168.1.50\3勝一\SE-37(彰濱)\01.工程圖面\01.ISO\ISO\1.(UG)FO-90401-S1P1FU-01.pdf | S5: 1
A6: 1 | B6: (UG)FO-90401-S1P1FU-01 | C6: 1/2 | D6: 5 | E6: 6 | F6: =IF(E6<>"",IF(Weld_list[[#This Row],[尺寸]]<1,1,E6),"") -> 6 | G6: S-10 | H6: 304 | I6: BW | J6: S | K6: 45974 | L6: VV | M6: 45977 | Q6: =HYPERLINK(_xlfn.CONCAT("\\192.168.1.50\3勝一\SE-37(彰濱)\01.工程圖面\01.ISO\ISO\",Weld_list[[#This Row],[流水號]],".",Weld_list[[#This Row],[DWG NO]],".pdf")) -> \\192.168.1.50\3勝一\SE-37(彰濱)\01.工程圖面\01.ISO\ISO\1.(UG)FO-90401-S1P1FU-01.pdf | S6: 1
A7: 1 | B7: (UG)FO-90401-S1P1FU-01 | C7: 1/2 | D7: 6 | E7: 6 | F7: =IF(E7<>"",IF(Weld_list[[#This Row],[尺寸]]<1,1,E7),"") -> 6 | G7: S-10 | H7: 304 | I7: BW | J7: S | K7: =IFERROR(TEXT(_xlfn.XLOOKUP(_xlfn.CONCAT(Weld_list[[#This Row],[流水號]],"_",Weld_list[[#This Row],[銲口編號]]),焊口登報表!D:D,焊口登報表!C:C,,0),"yyyy/mm/dd"),"") -> 2025/08/25 | L7: VV | M7: 45897 | Q7: =HYPERLINK(_xlfn.CONCAT("\\192.168.1.50\3勝一\SE-37(彰濱)\01.工程圖面\01.ISO\ISO\",Weld_list[[#This Row],[流水號]],".",Weld_list[[#This Row],[DWG NO]],".pdf")) -> \\192.168.1.50\3勝一\SE-37(彰濱)\01.工程圖面\01.ISO\ISO\1.(UG)FO-90401-S1P1FU-01.pdf | S7: 1
A8: 1 | B8: (UG)FO-90401-S1P1FU-01 | C8: 1/2 | D8: 7 | E8: 6 | F8: =IF(E8<>"",IF(Weld_list[[#This Row],[尺寸]]<1,1,E8),"") -> 6 | G8: S-10 | H8: 304 | I8: BW | J8: S | K8: =IFERROR(TEXT(_xlfn.XLOOKUP(_xlfn.CONCAT(Weld_list[[#This Row],[流水號]],"_",Weld_list[[#This Row],[銲口編號]]),焊口登報表!D:D,焊口登報表!C:C,,0),"yyyy/mm/dd"),"") -> 2025/08/25 | L8: VV | M8: 45897 | Q8: =HYPERLINK(_xlfn.CONCAT("\\192.168.1.50\3勝一\SE-37(彰濱)\01.工程圖面\01.ISO\ISO\",Weld_list[[#This Row],[流水號]],".",Weld_list[[#This Row],[DWG NO]],".pdf")) -> \\192.168.1.50\3勝一\SE-37(彰濱)\01.工程圖面\01.ISO\ISO\1.(UG)FO-90401-S1P1FU-01.pdf | S8: 1
A9: 1 | B9: (UG)FO-90401-S1P1FU-01 | C9: 1/2 | D9: 8 | E9: 6 | F9: =IF(E9<>"",IF(Weld_list[[#This Row],[尺寸]]<1,1,E9),"") -> 6 | G9: S-10 | H9: 304 | I9: BW | J9: S | K9: =IFERROR(TEXT(_xlfn.XLOOKUP(_xlfn.CONCAT(Weld_list[[#This Row],[流水號]],"_",Weld_list[[#This Row],[銲口編號]]),焊口登報表!D:D,焊口登報表!C:C,,0),"yyyy/mm/dd"),"") -> 2025/08/25 | L9: VV | M9: 45897 | Q9: =HYPERLINK(_xlfn.CONCAT("\\192.168.1.50\3勝一\SE-37(彰濱)\01.工程圖面\01.ISO\ISO\",Weld_list[[#This Row],[流水號]],".",Weld_list[[#This Row],[DWG NO]],".pdf")) -> \\192.168.1.50\3勝一\SE-37(彰濱)\01.工程圖面\01.ISO\ISO\1.(UG)FO-90401-S1P1FU-01.pdf | S9: 1
A10: 1 | B10: (UG)FO-90401-S1P1FU-01 | C10: 1/2 | D10: 9 | E10: 6 | F10: =IF(E10<>"",IF(Weld_list[[#This Row],[尺寸]]<1,1,E10),"") -> 6 | G10: S-10 | H10: 304 | I10: BW | J10: S | K10: 45974 | L10: VV | M10: 45977 | Q10: =HYPERLINK(_xlfn.CONCAT("\\192.168.1.50\3勝一\SE-37(彰濱)\01.工程圖面\01.ISO\ISO\",Weld_list[[#This Row],[流水號]],".",Weld_list[[#This Row],[DWG NO]],".pdf")) -> \\192.168.1.50\3勝一\SE-37(彰濱)\01.工程圖面\01.ISO\ISO\1.(UG)FO-90401-S1P1FU-01.pdf | S10: 1
A11: 1 | B11: (UG)FO-90401-S1P1FU-01 | C11: 1/2 | D11: 10 | E11: 6 | F11: =IF(E11<>"",IF(Weld_list[[#This Row],[尺寸]]<1,1,E11),"") -> 6 | G11: S-10 | H11: 304 | I11: BW | J11: S | K11: =IFERROR(TEXT(_xlfn.XLOOKUP(_xlfn.CONCAT(Weld_list[[#This Row],[流水號]],"_",Weld_list[[#This Row],[銲口編號]]),焊口登報表!D:D,焊口登報表!C:C,,0),"yyyy/mm/dd"),"") -> 2025/08/25 | L11: VV | M11: 45897 | Q11: =HYPERLINK(_xlfn.CONCAT("\\192.168.1.50\3勝一\SE-37(彰濱)\01.工程圖面\01.ISO\ISO\",Weld_list[[#This Row],[流水號]],".",Weld_list[[#This Row],[DWG NO]],".pdf")) -> \\192.168.1.50\3勝一\SE-37(彰濱)\01.工程圖面\01.ISO\ISO\1.(UG)FO-90401-S1P1FU-01.pdf | S11: 1
A12: 1 | B12: (UG)FO-90401-S1P1FU-01 | C12: 1/2 | D12: 11 | E12: 6 | F12: =IF(E12<>"",IF(Weld_list[[#This Row],[尺寸]]<1,1,E12),"") -> 6 | G12: S-10 | H12: 304 | I12: BW | J12: S | K12: =IFERROR(TEXT(_xlfn.XLOOKUP(_xlfn.CONCAT(Weld_list[[#This Row],[流水號]],"_",Weld_list[[#This Row],[銲口編號]]),焊口登報表!D:D,焊口登報表!C:C,,0),"yyyy/mm/dd"),"") -> 2025/08/25 | L12: VV | M12: 45897 | Q12: =HYPERLINK(_xlfn.CONCAT("\\192.168.1.50\3勝一\SE-37(彰濱)\01.工程圖面\01.ISO\ISO\",Weld_list[[#This Row],[流水號]],".",Weld_list[[#This Row],[DWG NO]],".pdf")) -> \\192.168.1.50\3勝一\SE-37(彰濱)\01.工程圖面\01.ISO\ISO\1.(UG)FO-90401-S1P1FU-01.pdf | S12: 1
A13: 1 | B13: (UG)FO-90401-S1P1FU-01 | C13: 1/2 | D13: 12 | E13: 6 | F13: =IF(E13<>"",IF(Weld_list[[#This Row],[尺寸]]<1,1,E13),"") -> 6 | G13: S-10 | H13: 304 | I13: BW | J13: S | K13: =IFERROR(TEXT(_xlfn.XLOOKUP(_xlfn.CONCAT(Weld_list[[#This Row],[流水號]],"_",Weld_list[[#This Row],[銲口編號]]),焊口登報表!D:D,焊口登報表!C:C,,0),"yyyy/mm/dd"),"") -> 2025/11/29 | L13: VV | M13: =IFERROR(TEXT(_xlfn.XLOOKUP(_xlfn.CONCAT(Weld_list[[#This Row],[流水號]],"_",Weld_list[[#This Row],[銲口編號]]),焊口登報表!F:F,焊口登報表!E:E,,0),"yyyy/mm/dd"),"") -> 2025/11/30 | Q13: =HYPERLINK(_xlfn.CONCAT("\\192.168.1.50\3勝一\SE-37(彰濱)\01.工程圖面\01.ISO\ISO\",Weld_list[[#This Row],[流水號]],".",Weld_list[[#This Row],[DWG NO]],".pdf")) -> \\192.168.1.50\3勝一\SE-37(彰濱)\01.工程圖面\01.ISO\ISO\1.(UG)FO-90401-S1P1FU-01.pdf | S13: 1
A14: 1 | B14: (UG)FO-90401-S1P1FU-01 | C14: 1/2 | D14: 13 | E14: 6 | F14: =IF(E14<>"",IF(Weld_list[[#This Row],[尺寸]]<1,1,E14),"") -> 6 | G14: S-10 | H14: 304 | I14: BW | J14: S | K14: =IFERROR(TEXT(_xlfn.XLOOKUP(_xlfn.CONCAT(Weld_list[[#This Row],[流水號]],"_",Weld_list[[#This Row],[銲口編號]]),焊口登報表!D:D,焊口登報表!C:C,,0),"yyyy/mm/dd"),"") -> 2025/08/25 | L14: VV | M14: 45897 | Q14: =HYPERLINK(_xlfn.CONCAT("\\192.168.1.50\3勝一\SE-37(彰濱)\01.工程圖面\01.ISO\ISO\",Weld_list[[#This Row],[流水號]],".",Weld_list[[#This Row],[DWG NO]],".pdf")) -> \\192.168.1.50\3勝一\SE-37(彰濱)\01.工程圖面\01.ISO\ISO\1.(UG)FO-90401-S1P1FU-01.pdf | S14: 1
A15: 1 | B15: (UG)FO-90401-S1P1FU-01 | C15: 1/2 | D15: 31 | E15: 6 | F15: =IF(E15<>"",IF(Weld_list[[#This Row],[尺寸]]<1,1,E15),"") -> 6 | G15: S-10 | H15: 304 | I15: BW | J15: S | K15: =IFERROR(TEXT(_xlfn.XLOOKUP(_xlfn.CONCAT(Weld_list[[#This Row],[流水號]],"_",Weld_list[[#This Row],[銲口編號]]),焊口登報表!D:D,焊口登報表!C:C,,0),"yyyy/mm/dd"),"") -> 2025/08/25 | L15: VV | M15: 45897 | Q15: =HYPERLINK(_xlfn.CONCAT("\\192.168.1.50\3勝一\SE-37(彰濱)\01.工程圖面\01.ISO\ISO\",Weld_list[[#This Row],[流水號]],".",Weld_list[[#This Row],[DWG NO]],".pdf")) -> \\192.168.1.50\3勝一\SE-37(彰濱)\01.工程圖面\01.ISO\ISO\1.(UG)FO-90401-S1P1FU-01.pdf | S15: 1
A16: 1 | B16: (UG)FO-90401-S1P1FU-01 | C16: 1/2 | D16: 32 | E16: 6 | F16: =IF(E16<>"",IF(Weld_list[[#This Row],[尺寸]]<1,1,E16),"") -> 6 | G16: S-10 | H16: 304 | I16: BW | J16: S | K16: =IFERROR(TEXT(_xlfn.XLOOKUP(_xlfn.CONCAT(Weld_list[[#This Row],[流水號]],"_",Weld_list[[#This Row],[銲口編號]]),焊口登報表!D:D,焊口登報表!C:C,,0),"yyyy/mm/dd"),"") -> 2025/11/29 | L16: VV | M16: =IFERROR(TEXT(_xlfn.XLOOKUP(_xlfn.CONCAT(Weld_list[[#This Row],[流水號]],"_",Weld_list[[#This Row],[銲口編號]]),焊口登報表!F:F,焊口登報表!E:E,,0),"yyyy/mm/dd"),"") -> 2025/11/30 | Q16: =HYPERLINK(_xlfn.CONCAT("\\192.168.1.50\3勝一\SE-37(彰濱)\01.工程圖面\01.ISO\ISO\",Weld_list[[#This Row],[流水號]],".",Weld_list[[#This Row],[DWG NO]],".pdf")) -> \\192.168.1.50\3勝一\SE-37(彰濱)\01.工程圖面\01.ISO\ISO\1.(UG)FO-90401-S1P1FU-01.pdf | S16: 1
A17: 1 | B17: (UG)FO-90401-S1P1FU-01 | C17: 1/2 | D17: 33 | E17: 6 | F17: =IF(E17<>"",IF(Weld_list[[#This Row],[尺寸]]<1,1,E17),"") -> 6 | G17: S-10 | H17: 304 | I17: BW | J17: S | K17: =IFERROR(TEXT(_xlfn.XLOOKUP(_xlfn.CONCAT(Weld_list[[#This Row],[流水號]],"_",Weld_list[[#This Row],[銲口編號]]),焊口登報表!D:D,焊口登報表!C:C,,0),"yyyy/mm/dd"),"") -> 2025/08/25 | L17: VV | M17: 45897 | Q17: =HYPERLINK(_xlfn.CONCAT("\\192.168.1.50\3勝一\SE-37(彰濱)\01.工程圖面\01.ISO\ISO\",Weld_list[[#This Row],[流水號]],".",Weld_list[[#This Row],[DWG NO]],".pdf")) -> \\192.168.1.50\3勝一\SE-37(彰濱)\01.工程圖面\01.ISO\ISO\1.(UG)FO-90401-S1P1FU-01.pdf | S17: 1
A18: 1-1 | B18: (UG)FO-90401-S1P1FU-02 | C18: 2/2 | D18: 21 | E18: 6 | F18: =IF(E18<>"",IF(Weld_list[[#This Row],[尺寸]]<1,1,E18),"") -> 6 | G18: S-10 | H18: 304 | I18: BW | J18: S | K18: =IFERROR(TEXT(_xlfn.XLOOKUP(_xlfn.CONCAT(Weld_list[[#This Row],[流水號]],"_",Weld_list[[#This Row],[銲口編號]]),焊口登報表!D:D,焊口登報表!C:C,,0),"yyyy/mm/dd"),"") -> 2025/08/25 | L18: VV | M18: 45897 | Q18: =HYPERLINK(_xlfn.CONCAT("\\192.168.1.50\3勝一\SE-37(彰濱)\01.工程圖面\01.ISO\ISO\",Weld_list[[#This Row],[流水號]],".",Weld_list[[#This Row],[DWG NO]],".pdf")) -> \\192.168.1.50\3勝一\SE-37(彰濱)\01.工程圖面\01.ISO\ISO\1-1.(UG)FO-90401-S1P1FU-02.pdf | S18: 1
A19: 1-1 | B19: (UG)FO-90401-S1P1FU-02 | C19: 2/2 | D19: 34 | E19: 6 | F19: =IF(E19<>"",IF(Weld_list[[#This Row],[尺寸]]<1,1,E19),"") -> 6 | G19: S-10 | H19: 304 | I19: BW | J19: S | K19: =IFERROR(TEXT(_xlfn.XLOOKUP(_xlfn.CONCAT(Weld_list[[#This Row],[流水號]],"_",Weld_list[[#This Row],[銲口編號]]),焊口登報表!D:D,焊口登報表!C:C,,0),"yyyy/mm/dd"),"") -> 2025/08/25 | L19: VV | M19: 45897 | Q19: =HYPERLINK(_xlfn.CONCAT("\\192.168.1.50\3勝一\SE-37(彰濱)\01.工程圖面\01.ISO\ISO\",Weld_list[[#This Row],[流水號]],".",Weld_list[[#This Row],[DWG NO]],".pdf")) -> \\192.168.1.50\3勝一\SE-37(彰濱)\01.工程圖面\01.ISO\ISO\1-1.(UG)FO-90401-S1P1FU-02.pdf | S19: 1
A20: 1-1 | B20: (UG)FO-90401-S1P1FU-02 | C20: 2/2 | D20: 35 | E20: 6 | F20: =IF(E20<>"",IF(Weld_list[[#This Row],[尺寸]]<1,1,E20),"") -> 6 | G20: S-10 | H20: 304 | I20: BW | J20: S | K20: =IFERROR(TEXT(_xlfn.XLOOKUP(_xlfn.CONCAT(Weld_list[[#This Row],[流水號]],"_",Weld_list[[#This Row],[銲口編號]]),焊口登報表!D:D,焊口登報表!C:C,,0),"yyyy/mm/dd"),"") -> 2025/08/25 | L20: VV | M20: 45897 | Q20: =HYPERLINK(_xlfn.CONCAT("\\192.168.1.50\3勝一\SE-37(彰濱)\01.工程圖面\01.ISO\ISO\",Weld_list[[#This Row],[流水號]],".",Weld_list[[#This Row],[DWG NO]],".pdf")) -> \\192.168.1.50\3勝一\SE-37(彰濱)\01.工程圖面\01.ISO\ISO\1-1.(UG)FO-90401-S1P1FU-02.pdf | S20: 1
A21: 1-1 | B21: (UG)FO-90401-S1P1FU-02 | C21: 2/2 | D21: 36 | E21: 6 | F21: =IF(E21<>"",IF(Weld_list[[#This Row],[尺寸]]<1,1,E21),"") -> 6 | G21: S-10 | H21: 304 | I21: BW | J21: S | K21: =IFERROR(TEXT(_xlfn.XLOOKUP(_xlfn.CONCAT(Weld_list[[#This Row],[流水號]],"_",Weld_list[[#This Row],[銲口編號]]),焊口登報表!D:D,焊口登報表!C:C,,0),"yyyy/mm/dd"),"") -> 2025/11/29 | L21: VV | M21: =IFERROR(TEXT(_xlfn.XLOOKUP(_xlfn.CONCAT(Weld_list[[#This Row],[流水號]],"_",Weld_list[[#This Row],[銲口編號]]),焊口登報表!F:F,焊口登報表!E:E,,0),"yyyy/mm/dd"),"") -> 2025/11/30 | Q21: =HYPERLINK(_xlfn.CONCAT("\\192.168.1.50\3勝一\SE-37(彰濱)\01.工程圖面\01.ISO\ISO\",Weld_list[[#This Row],[流水號]],".",Weld_list[[#This Row],[DWG NO]],".pdf")) -> \\192.168.1.50\3勝一\SE-37(彰濱)\01.工程圖面\01.ISO\ISO\1-1.(UG)FO-90401-S1P1FU-02.pdf | S21: 1
A22: 1-1 | B22: (UG)FO-90401-S1P1FU-02 | C22: 2/2 | D22: 37 | E22: 4 | F22: =IF(E22<>"",IF(Weld_list[[#This Row],[尺寸]]<1,1,E22),"") -> 4 | G22: S-10 | H22: 304 | I22: BW | J22: S | K22: =IFERROR(TEXT(_xlfn.XLOOKUP(_xlfn.CONCAT(Weld_list[[#This Row],[流水號]],"_",Weld_list[[#This Row],[銲口編號]]),焊口登報表!D:D,焊口登報表!C:C,,0),"yyyy/mm/dd"),"") -> 2025/11/29 | L22: VV | M22: =IFERROR(TEXT(_xlfn.XLOOKUP(_xlfn.CONCAT(Weld_list[[#This Row],[流水號]],"_",Weld_list[[#This Row],[銲口編號]]),焊口登報表!F:F,焊口登報表!E:E,,0),"yyyy/mm/dd"),"") -> 2025/11/30 | Q22: =HYPERLINK(_xlfn.CONCAT("\\192.168.1.50\3勝一\SE-37(彰濱)\01.工程圖面\01.ISO\ISO\",Weld_list[[#This Row],[流水號]],".",Weld_list[[#This Row],[DWG NO]],".pdf")) -> \\192.168.1.50\3勝一\SE-37(彰濱)\01.工程圖面\01.ISO\ISO\1-1.(UG)FO-90401-S1P1FU-02.pdf | S22: 1
A23: 1-1 | B23: (UG)FO-90401-S1P1FU-02 | C23: 2/2 | D23: 38 | E23: 1.5 | F23: =IF(E23<>"",IF(Weld_list[[#This Row],[尺寸]]<1,1,E23),"") -> 1.5 | G23: S-40 | H23: 304 | I23: IW | J23: S | K23: =IFERROR(TEXT(_xlfn.XLOOKUP(_xlfn.CONCAT(Weld_list[[#This Row],[流水號]],"_",Weld_list[[#This Row],[銲口編號]]),焊口登報表!D:D,焊口登報表!C:C,,0),"yyyy/mm/dd"),"") -> 2025/08/25 | L23: V | M23: 45897 | Q23: =HYPERLINK(_xlfn.CONCAT("\\192.168.1.50\3勝一\SE-37(彰濱)\01.工程圖面\01.ISO\ISO\",Weld_list[[#This Row],[流水號]],".",Weld_list[[#This Row],[DWG NO]],".pdf")) -> \\192.168.1.50\3勝一\SE-37(彰濱)\01.工程圖面\01.ISO\ISO\1-1.(UG)FO-90401-S1P1FU-02.pdf | R23: =IF(Weld_list[[#This Row],[組銲完成日期]]<>"","已完成","未完成") -> 已完成 | S23: 1
A24: 1-1 | B24: (UG)FO-90401-S1P1FU-02 | C24: 2/2 | D24: 39 | E24: 4 | F24: =IF(E24<>"",IF(Weld_list[[#This Row],[尺寸]]<1,1,E24),"") -> 4 | G24: S-10 | H24: 304 | I24: BW | J24: S | K24: =IFERROR(TEXT(_xlfn.XLOOKUP(_xlfn.CONCAT(Weld_list[[#This Row],[流水號]],"_",Weld_list[[#This Row],[銲口編號]]),焊口登報表!D:D,焊口登報表!C:C,,0),"yyyy/mm/dd"),"") -> 2025/08/25 | L24: VV | M24: 45897 | Q24: =HYPERLINK(_xlfn.CONCAT("\\192.168.1.50\3勝一\SE-37(彰濱)\01.工程圖面\01.ISO\ISO\",Weld_list[[#This Row],[流水號]],".",Weld_list[[#This Row],[DWG NO]],".pdf")) -> \\192.168.1.50\3勝一\SE-37(彰濱)\01.工程圖面\01.ISO\ISO\1-1.(UG)FO-90401-S1P1FU-02.pdf | R24: =IF(Weld_list[[#This Row],[組銲完成日期]]<>"","已完成","未完成") -> 已完成 | S24: 1
A25: 1-1 | B25: (UG)FO-90401-S1P1FU-02 | C25: 2/2 | D25: 39V | E25: 4 | F25: =IF(E25<>"",IF(Weld_list[[#This Row],[尺寸]]<1,1,E25),"") -> 4 | G25: S-10 | H25: 304 | I25: FF | J25: F | K25: =IFERROR(TEXT(_xlfn.XLOOKUP(_xlfn.CONCAT(Weld_list[[#This Row],[流水號]],"_",Weld_list[[#This Row],[銲口編號]]),焊口登報表!D:D,焊口登報表!C:C,,0),"yyyy/mm/dd"),"") | M25: =IFERROR(TEXT(_xlfn.XLOOKUP(_xlfn.CONCAT(Weld_list[[#This Row],[流水號]],"_",Weld_list[[#This Row],[銲口編號]]),焊口登報表!F:F,焊口登報表!E:E,,0),"yyyy/mm/dd"),"") | P25: =_xlfn.TEXTJOIN("-",TRUE,INDEX(_xlfn.TEXTSPLIT(B25,"-"),1),INDEX(_xlfn.TEXTSPLIT(B25,"-"),2),INDEX(_xlfn.TEXTSPLIT(B25,"-"),3),INDEX(_xlfn.TEXTSPLIT(B25,"-"),4),INDEX(_xlfn.TEXTSPLIT(B25,"-"),5)) -> #REF! | Q25: =HYPERLINK(_xlfn.CONCAT("\\192.168.1.50\3勝一\SE-37(彰濱)\01.工程圖面\01.ISO\ISO\",Weld_list[[#This Row],[流水號]],".",Weld_list[[#This Row],[DWG NO]],".pdf")) -> \\192.168.1.50\3勝一\SE-37(彰濱)\01.工程圖面\01.ISO\ISO\1-1.(UG)FO-90401-S1P1FU-02.pdf | R25: =IF(Weld_list[[#This Row],[組銲完成日期]]<>"","已完成","未完成") -> 未完成 | S25: 1
A26: 1-1 | B26: (UG)FO-90401-S1P1FU-02 | C26: 2/2 | D26: 40 | E26: 1.5 | F26: =IF(E26<>"",IF(Weld_list[[#This Row],[尺寸]]<1,1,E26),"") -> 1.5 | G26: S-40 | H26: 304 | I26: SW | J26: S | K26: =IFERROR(TEXT(_xlfn.XLOOKUP(_xlfn.CONCAT(Weld_list[[#This Row],[流水號]],"_",Weld_list[[#This Row],[銲口編號]]),焊口登報表!D:D,焊口登報表!C:C,,0),"yyyy/mm/dd"),"") -> 2025/08/25 | L26: V | M26: 45897 | Q26: =HYPERLINK(_xlfn.CONCAT("\\192.168.1.50\3勝一\SE-37(彰濱)\01.工程圖面\01.ISO\ISO\",Weld_list[[#This Row],[流水號]],".",Weld_list[[#This Row],[DWG NO]],".pdf")) -> \\192.168.1.50\3勝一\SE-37(彰濱)\01.工程圖面\01.ISO\ISO\1-1.(UG)FO-90401-S1P1FU-02.pdf | R26: =IF(Weld_list[[#This Row],[組銲完成日期]]<>"","已完成","未完成") -> 已完成 | S26: 1
A27: 1-1 | B27: (UG)FO-90401-S1P1FU-02 | C27: 2/2 | D27: 41 | E27: 1.5 | F27: =IF(E27<>"",IF(Weld_list[[#This Row],[尺寸]]<1,1,E27),"") -> 1.5 | G27: S-40 | H27: 304 | I27: SW | J27: S | K27: =IFERROR(TEXT(_xlfn.XLOOKUP(_xlfn.CONCAT(Weld_list[[#This Row],[流水號]],"_",Weld_list[[#This Row],[銲口編號]]),焊口登報表!D:D,焊口登報表!C:C,,0),"yyyy/mm/dd"),"") -> 2025/08/25 | L27: V | M27: 45897 | Q27: =HYPERLINK(_xlfn.CONCAT("\\192.168.1.50\3勝一\SE-37(彰濱)\01.工程圖面\01.ISO\ISO\",Weld_list[[#This Row],[流水號]],".",Weld_list[[#This Row],[DWG NO]],".pdf")) -> \\192.168.1.50\3勝一\SE-37(彰濱)\01.工程圖面\01.ISO\ISO\1-1.(UG)FO-90401-S1P1FU-02.pdf | R27: =IF(Weld_list[[#This Row],[組銲完成日期]]<>"","已完成","未完成") -> 已完成 | S27: 1
A28: 1-1 | B28: (UG)FO-90401-S1P1FU-02 | C28: 2/2 | D28: 42 | E28: 1.5 | F28: =IF(E28<>"",IF(Weld_list[[#This Row],[尺寸]]<1,1,E28),"") -> 1.5 | G28: S-40 | H28: 304 | I28: SW | J28: S | K28: =IFERROR(TEXT(_xlfn.XLOOKUP(_xlfn.CONCAT(Weld_list[[#This Row],[流水號]],"_",Weld_list[[#This Row],[銲口編號]]),焊口登報表!D:D,焊口登報表!C:C,,0),"yyyy/mm/dd"),"") -> 2025/08/25 | L28: V | M28: 45897 | Q28: =HYPERLINK(_xlfn.CONCAT("\\192.168.1.50\3勝一\SE-37(彰濱)\01.工程圖面\01.ISO\ISO\",Weld_list[[#This Row],[流水號]],".",Weld_list[[#This Row],[DWG NO]],".pdf")) -> \\192.168.1.50\3勝一\SE-37(彰濱)\01.工程圖面\01.ISO\ISO\1-1.(UG)FO-90401-S1P1FU-02.pdf | R28: =IF(Weld_list[[#This Row],[組銲完成日期]]<>"","已完成","未完成") -> 已完成 | S28: 1
A29: 1-1 | B29: (UG)FO-90401-S1P1FU-02 | C29: 2/2 | D29: 43 | E29: 1.5 | F29: =IF(E29<>"",IF(Weld_list[[#This Row],[尺寸]]<1,1,E29),"") -> 1.5 | G29: S-40 | H29: 304 | I29: T | J29: F | K29: =IFERROR(TEXT(_xlfn.XLOOKUP(_xlfn.CONCAT(Weld_list[[#This Row],[流水號]],"_",Weld_list[[#This Row],[銲口編號]]),焊口登報表!D:D,焊口登報表!C:C,,0),"yyyy/mm/dd"),"") | M29: =IFERROR(TEXT(_xlfn.XLOOKUP(_xlfn.CONCAT(Weld_list[[#This Row],[流水號]],"_",Weld_list[[#This Row],[銲口編號]]),焊口登報表!F:F,焊口登報表!E:E,,0),"yyyy/mm/dd"),"") | P29: =_xlfn.TEXTJOIN("-",TRUE,INDEX(_xlfn.TEXTSPLIT(B29,"-"),1),INDEX(_xlfn.TEXTSPLIT(B29,"-"),2),INDEX(_xlfn.TEXTSPLIT(B29,"-"),3),INDEX(_xlfn.TEXTSPLIT(B29,"-"),4),INDEX(_xlfn.TEXTSPLIT(B29,"-"),5)) -> #REF! | Q29: =HYPERLINK(_xlfn.CONCAT("\\192.168.1.50\3勝一\SE-37(彰濱)\01.工程圖面\01.ISO\ISO\",Weld_list[[#This Row],[流水號]],".",Weld_list[[#This Row],[DWG NO]],".pdf")) -> \\192.168.1.50\3勝一\SE-37(彰濱)\01.工程圖面\01.ISO\ISO\1-1.(UG)FO-90401-S1P1FU-02.pdf | R29: =IF(Weld_list[[#This Row],[組銲完成日期]]<>"","已完成","未完成") -> 未完成 | S29: 1
A30: 2 | B30: (UG)FO-90401.-S1P1FU-01 | C30: 1/2 | D30: 1 | E30: 6 | F30: =IF(E30<>"",IF(Weld_list[[#This Row],[尺寸]]<1,1,E30),"") -> 6 | G30: S-10 | H30: 304 | I30: BW | J30: S | K30: =IFERROR(TEXT(_xlfn.XLOOKUP(_xlfn.CONCAT(Weld_list[[#This Row],[流水號]],"_",Weld_list[[#This Row],[銲口編號]]),焊口登報表!D:D,焊口登報表!C:C,,0),"yyyy/mm/dd"),"") -> 2025/08/25 | L30: VV | M30: 45897 | Q30: =HYPERLINK(_xlfn.CONCAT("\\192.168.1.50\3勝一\SE-37(彰濱)\01.工程圖面\01.ISO\ISO\",Weld_list[[#This Row],[流水號]],".",Weld_list[[#This Row],[DWG NO]],".pdf")) -> \\192.168.1.50\3勝一\SE-37(彰濱)\01.工程圖面\01.ISO\ISO\2.(UG)FO-90401.-S1P1FU-01.pdf | S30: 1
A31: 2 | B31: (UG)FO-90401.-S1P1FU-01 | C31: 1/2 | D31: 2 | E31: 6 | F31: =IF(E31<>"",IF(Weld_list[[#This Row],[尺寸]]<1,1,E31),"") -> 6 | G31: S-10 | H31: 304 | I31: BW | J31: S | K31: =IFERROR(TEXT(_xlfn.XLOOKUP(_xlfn.CONCAT(Weld_list[[#This Row],[流水號]],"_",Weld_list[[#This Row],[銲口編號]]),焊口登報表!D:D,焊口登報表!C:C,,0),"yyyy/mm/dd"),"") -> 2025/08/25 | L31: VV | M31: 45897 | Q31: =HYPERLINK(_xlfn.CONCAT("\\192.168.1.50\3勝一\SE-37(彰濱)\01.工程圖面\01.ISO\ISO\",Weld_list[[#This Row],[流水號]],".",Weld_list[[#This Row],[DWG NO]],".pdf")) -> \\192.168.1.50\3勝一\SE-37(彰濱)\01.工程圖面\01.ISO\ISO\2.(UG)FO-90401.-S1P1FU-01.pdf | S31: 1
A32: 2 | B32: (UG)FO-90401.-S1P1FU-01 | C32: 1/2 | D32: 3 | E32: 6 | F32: =IF(E32<>"",IF(Weld_list[[#This Row],[尺寸]]<1,1,E32),"") -> 6 | G32: S-10 | H32: 304 | I32: BW | J32: S | K32: =IFERROR(TEXT(_xlfn.XLOOKUP(_xlfn.CONCAT(Weld_list[[#This Row],[流水號]],"_",Weld_list[[#This Row],[銲口編號]]),焊口登報表!D:D,焊口登報表!C:C,,0),"yyyy/mm/dd"),"") -> 2025/08/25 | L32: VV | M32: 45897 | Q32: =HYPERLINK(_xlfn.CONCAT("\\192.168.1.50\3勝一\SE-37(彰濱)\01.工程圖面\01.ISO\ISO\",Weld_list[[#This Row],[流水號]],".",Weld_list[[#This Row],[DWG NO]],".pdf")) -> \\192.168.1.50\3勝一\SE-37(彰濱)\01.工程圖面\01.ISO\ISO\2.(UG)FO-90401.-S1P1FU-01.pdf | S32: 1
A33: 2 | B33: (UG)FO-90401.-S1P1FU-01 | C33: 1/2 | D33: 4 | E33: 6 | F33: =IF(E33<>"",IF(Weld_list[[#This Row],[尺寸]]<1,1,E33),"") -> 6 | G33: S-10 | H33: 304 | I33: BW | J33: S | K33: =IFERROR(TEXT(_xlfn.XLOOKUP(_xlfn.CONCAT(Weld_list[[#This Row],[流水號]],"_",Weld_list[[#This Row],[銲口編號]]),焊口登報表!D:D,焊口登報表!C:C,,0),"yyyy/mm/dd"),"") -> 2025/08/25 | L33: VV | M33: 45897 | Q33: =HYPERLINK(_xlfn.CONCAT("\\192.168.1.50\3勝一\SE-37(彰濱)\01.工程圖面\01.ISO\ISO\",Weld_list[[#This Row],[流水號]],".",Weld_list[[#This Row],[DWG NO]],".pdf")) -> \\192.168.1.50\3勝一\SE-37(彰濱)\01.工程圖面\01.ISO\ISO\2.(UG)FO-90401.-S1P1FU-01.pdf | S33: 1
A34: 2 | B34: (UG)FO-90401.-S1P1FU-01 | C34: 1/2 | D34: 5 | E34: 6 | F34: =IF(E34<>"",IF(Weld_list[[#This Row],[尺寸]]<1,1,E34),"") -> 6 | G34: S-10 | H34: 304 | I34: BW | J34: S | K34: =IFERROR(TEXT(_xlfn.XLOOKUP(_xlfn.CONCAT(Weld_list[[#This Row],[流水號]],"_",Weld_list[[#This Row],[銲口編號]]),焊口登報表!D:D,焊口登報表!C:C,,0),"yyyy/mm/dd"),"") -> 2025/08/25 | L34: VV | M34: 45897 | Q34: =HYPERLINK(_xlfn.CONCAT("\\192.168.1.50\3勝一\SE-37(彰濱)\01.工程圖面\01.ISO\ISO\",Weld_list[[#This Row],[流水號]],".",Weld_list[[#This Row],[DWG NO]],".pdf")) -> \\192.168.1.50\3勝一\SE-37(彰濱)\01.工程圖面\01.ISO\ISO\2.(UG)FO-90401.-S1P1FU-01.pdf | S34: 1
A35: 2 | B35: (UG)FO-90401.-S1P1FU-01 | C35: 1/2 | D35: 6 | E35: 6 | F35: =IF(E35<>"",IF(Weld_list[[#This Row],[尺寸]]<1,1,E35),"") -> 6 | G35: S-10 | H35: 304 | I35: BW | J35: S | K35: =IFERROR(TEXT(_xlfn.XLOOKUP(_xlfn.CONCAT(Weld_list[[#This Row],[流水號]],"_",Weld_list[[#This Row],[銲口編號]]),焊口登報表!D:D,焊口登報表!C:C,,0),"yyyy/mm/dd"),"") -> 2025/08/25 | L35: VV | M35: 45897 | Q35: =HYPERLINK(_xlfn.CONCAT("\\192.168.1.50\3勝一\SE-37(彰濱)\01.工程圖面\01.ISO\ISO\",Weld_list[[#This Row],[流水號]],".",Weld_list[[#This Row],[DWG NO]],".pdf")) -> \\192.168.1.50\3勝一\SE-37(彰濱)\01.工程圖面\01.ISO\ISO\2.(UG)FO-90401.-S1P1FU-01.pdf | S35: 1
A36: 2 | B36: (UG)FO-90401.-S1P1FU-01 | C36: 1/2 | D36: 7 | E36: 6 | F36: =IF(E36<>"",IF(Weld_list[[#This Row],[尺寸]]<1,1,E36),"") -> 6 | G36: S-10 | H36: 304 | I36: BW | J36: S | K36: =IFERROR(TEXT(_xlfn.XLOOKUP(_xlfn.CONCAT(Weld_list[[#This Row],[流水號]],"_",Weld_list[[#This Row],[銲口編號]]),焊口登報表!D:D,焊口登報表!C:C,,0),"yyyy/mm/dd"),"") -> 2025/12/20 | L36: VV | M36: =IFERROR(TEXT(_xlfn.XLOOKUP(_xlfn.CONCAT(Weld_list[[#This Row],[流水號]],"_",Weld_list[[#This Row],[銲口編號]]),焊口登報表!F:F,焊口登報表!E:E,,0),"yyyy/mm/dd"),"") -> 2025/12/21 | P36: =_xlfn.TEXTJOIN("-",TRUE,INDEX(_xlfn.TEXTSPLIT(B36,"-"),1),INDEX(_xlfn.TEXTSPLIT(B36,"-"),2),INDEX(_xlfn.TEXTSPLIT(B36,"-"),3),INDEX(_xlfn.TEXTSPLIT(B36,"-"),4),INDEX(_xlfn.TEXTSPLIT(B36,"-"),5)) -> #REF! | Q36: =HYPERLINK(_xlfn.CONCAT("\\192.168.1.50\3勝一\SE-37(彰濱)\01.工程圖面\01.ISO\ISO\",Weld_list[[#This Row],[流水號]],".",Weld_list[[#This Row],[DWG NO]],".pdf")) -> \\192.168.1.50\3勝一\SE-37(彰濱)\01.工程圖面\01.ISO\ISO\2.(UG)FO-90401.-S1P1FU-01.pdf | R36: =IF(Weld_list[[#This Row],[組銲完成日期]]<>"","已完成","未完成") -> 已完成 | S36: 1
A37: 2 | B37: (UG)FO-90401.-S1P1FU-01 | C37: 1/2 | D37: 19 | E37: 6 | F37: =IF(E37<>"",IF(Weld_list[[#This Row],[尺寸]]<1,1,E37),"") -> 6 | G37: S-10 | H37: 304 | I37: BW | J37: S | K37: =IFERROR(TEXT(_xlfn.XLOOKUP(_xlfn.CONCAT(Weld_list[[#This Row],[流水號]],"_",Weld_list[[#This Row],[銲口編號]]),焊口登報表!D:D,焊口登報表!C:C,,0),"yyyy/mm/dd"),"") -> 2025/08/25 | L37: VV | M37: 45897 | Q37: =HYPERLINK(_xlfn.CONCAT("\\192.168.1.50\3勝一\SE-37(彰濱)\01.工程圖面\01.ISO\ISO\",Weld_list[[#This Row],[流水號]],".",Weld_list[[#This Row],[DWG NO]],".pdf")) -> \\192.168.1.50\3勝一\SE-37(彰濱)\01.工程圖面\01.ISO\ISO\2.(UG)FO-90401.-S1P1FU-01.pdf | S37: 1
A38: 2 | B38: (UG)FO-90401.-S1P1FU-01 | C38: 1/2 | D38: 20 | E38: 6 | F38: =IF(E38<>"",IF(Weld_list[[#This Row],[尺寸]]<1,1,E38),"") -> 6 | G38: S-10 | H38: 304 | I38: BW | J38: S | K38: =IFERROR(TEXT(_xlfn.XLOOKUP(_xlfn.CONCAT(Weld_list[[#This Row],[流水號]],"_",Weld_list[[#This Row],[銲口編號]]),焊口登報表!D:D,焊口登報表!C:C,,0),"yyyy/mm/dd"),"") -> 2025/08/25 | L38: VV | M38: 45897 | Q38: =HYPERLINK(_xlfn.CONCAT("\\192.168.1.50\3勝一\SE-37(彰濱)\01.工程圖面\01.ISO\ISO\",Weld_list[[#This Row],[流水號]],".",Weld_list[[#This Row],[DWG NO]],".pdf")) -> \\192.168.1.50\3勝一\SE-37(彰濱)\01.工程圖面\01.ISO\ISO\2.(UG)FO-90401.-S1P1FU-01.pdf | S38: 1
A39: 2 | B39: (UG)FO-90401.-S1P1FU-01 | C39: 1/2 | D39: 20V | E39: 6 | F39: =IF(E39<>"",IF(Weld_list[[#This Row],[尺寸]]<1,1,E39),"") -> 6 | G39: S-10 | H39: 304 | I39: FF | J39: F | K39: =IFERROR(TEXT(_xlfn.XLOOKUP(_xlfn.CONCAT(Weld_list[[#This Row],[流水號]],"_",Weld_list[[#This Row],[銲口編號]]),焊口登報表!D:D,焊口登報表!C:C,,0),"yyyy/mm/dd"),"") | M39: =IFERROR(TEXT(_xlfn.XLOOKUP(_xlfn.CONCAT(Weld_list[[#This Row],[流水號]],"_",Weld_list[[#This Row],[銲口編號]]),焊口登報表!F:F,焊口登報表!E:E,,0),"yyyy/mm/dd"),"") | P39: =_xlfn.TEXTJOIN("-",TRUE,INDEX(_xlfn.TEXTSPLIT(B39,"-"),1),INDEX(_xlfn.TEXTSPLIT(B39,"-"),2),INDEX(_xlfn.TEXTSPLIT(B39,"-"),3),INDEX(_xlfn.TEXTSPLIT(B39,"-"),4),INDEX(_xlfn.TEXTSPLIT(B39,"-"),5)) -> #REF! | Q39: =HYPERLINK(_xlfn.CONCAT("\\192.168.1.50\3勝一\SE-37(彰濱)\01.工程圖面\01.ISO\ISO\",Weld_list[[#This Row],[流水號]],".",Weld_list[[#This Row],[DWG NO]],".pdf")) -> \\192.168.1.50\3勝一\SE-37(彰濱)\01.工程圖面\01.ISO\ISO\2.(UG)FO-90401.-S1P1FU-01.pdf | R39: =IF(Weld_list[[#This Row],[組銲完成日期]]<>"","已完成","未完成") -> 未完成 | S39: 1
A40: 2 | B40: (UG)FO-90401.-S1P1FU-01 | C40: 1/2 | D40: 21 | E40: 6 | F40: =IF(E40<>"",IF(Weld_list[[#This Row],[尺寸]]<1,1,E40),"") -> 6 | G40: S-10 | H40: 304 | I40: BW | J40: S | K40: =IFERROR(TEXT(_xlfn.XLOOKUP(_xlfn.CONCAT(Weld_list[[#This Row],[流水號]],"_",Weld_list[[#This Row],[銲口編號]]),焊口登報表!D:D,焊口登報表!C:C,,0),"yyyy/mm/dd"),"") -> 2025/08/25 | L40: VV | M40: 45897 | Q40: =HYPERLINK(_xlfn.CONCAT("\\192.168.1.50\3勝一\SE-37(彰濱)\01.工程圖面\01.ISO\ISO\",Weld_list[[#This Row],[流水號]],".",Weld_list[[#This Row],[DWG NO]],".pdf")) -> \\192.168.1.50\3勝一\SE-37(彰濱)\01.工程圖面\01.ISO\ISO\2.(UG)FO-90401.-S1P1FU-01.pdf | R40: =IF(Weld_list[[#This Row],[組銲完成日期]]<>"","已完成","未完成") -> 已完成 | S40: 1
...

Sheet RTPT清單
A1: RT.PT檢驗日期 | B1: 45897
A2: RT.PT檢驗焊口 | B2: V
A4: 計數 - 銲口編號
A5: 材質 | B5: 尺寸 | C5: 厚度 | D5: 流水號 | E5: DWG NO | F5: 銲口編號 | G5: 合計
A6: 304 | B6: 1 | C6: S-40 | D6: 30 | E6: (UG)WW-18041-S1P4U-01 | F6: 10 | G6: 1
F7: 11 | G7: 1
F8: 12 | G8: 1
F9: 15 | G9: 1
F10: 16 | G10: 1
F11: 1001 | G11: 1
D12: 34 | E12: (UG)WW-18048-S1P4U-01 | F12: 4 | G12: 1
F13: 5 | G13: 1
F14: 12 | G14: 1
F15: 13 | G15: 1
F16: 16 | G16: 1
F17: 17 | G17: 1
B18: 1.5 | C18: S-40 | D18: 3 | E18: (UG)FO-90401.-S1P1FU-02 | F18: 24 | G18: 1
F19: 26 | G19: 1
F20: 27 | G20: 1
F21: 28 | G21: 1
D22: 1-1 | E22: (UG)FO-90401-S1P1FU-02 | F22: 38 | G22: 1
F23: 40 | G23: 1
F24: 41 | G24: 1
F25: 42 | G25: 1
A26: GALV | B26: 0.5 | C26: S-40 | D26: 6 | E26: (UG)FW-90201.-C1AU-02 | F26: 26 | G26: 1
C27: S-80 | D27: 6 | E27: (UG)FW-90201.-C1AU-02 | F27: 27 | G27: 1
F28: 28 | G28: 1
D29: 9 | E29: (UG)FW-90201..-C1AU-02 | F29: 25 | G29: 1
F30: 26 | G30: 1
F31: 27 | G31: 1
D32: 11 | E32: (UG)FW-90201...-C1AU-02 | F32: 15 | G32: 1
F33: 16 | G33: 1
F34: 17 | G34: 1
B35: 2.5 | C35: S-40 | D35: 10 | E35: (UG)FW-90201...-C1AU-01 | F35: 6 | G35: 1
A36: 總計 | G36: 30

Sheet 缺焊口清單
A1: 流水號 | B1: 圖面問題
A2: 11 | B2: 欠全接頭,新增焊口
A3: 20 | B3: 欠全接頭,新增焊口
A4: 131 | B4: 欠全接頭,新增焊口
A5: 134 | B5: 欠全接頭,新增焊口
A6: 135 | B6: 欠全接頭,新增焊口
A7: 142 | B7: 欠全接頭,新增焊口
A8: 148 | B8: 新增焊口
A9: 150 | B9: 新增焊口
A10: 151 | B10: 新增焊口
A11: 154 | B11: 新增焊口
A12: 156 | B12: 新增焊口
A13: 159 | B13: 欠全接頭,新增焊口
... A41: 529 | B41: 新增焊口

Sheet 接頭需求
A1: 流水號 | B1: 需購買管接頭數量 | C1: 尺寸 | D1: 材質
A2: 11 | B2: 1 | C2: 1 | D2: 304
A3: 20 | B3: 2 | C3: 1 | D3: 304
A4: 68 | B4: 1 | C4: 0.5 | D4: C.S
A5: 89 | B5: 1 | C5: 1 | D5: C.S
A6: 131 | B6: 1 | C6: 1 | D6: C.S
A7: 134 | B7: 1 | C7: 1 | D7: C.S
A8: 135 | B8: 1 | C8: 1 | D8: C.S
A9: 142 | B9: 2 | C9: 1 | D9: C.S
A10: 159 | B10: 1 | C10: 0.5 | D10: 304
A11: 162 | B11: 1 | C11: 1 | D11: 304
A12: 173 | B12: 1 | C12: 1.5 | D12: 304
A13: 183 | B13: 1 | C13: 1 | D13: 304
... A34: 570 | B34: 2 | C34: 1.5 | D34: 304

Sheet 焊口登報表
A1: 流水號 | B1: 編號 | C1: 日期 | D1: id | E1: 日期 | F1: id
A2: 4 | B2: 1 | C2: 45875 | D2: =_xlfn.CONCAT(A2,"_",B2) -> 4_1
A3: 4 | B3: 2 | C3: 45875 | D3: =_xlfn.CONCAT(A3,"_",B3) -> 4_2
A4: 4 | B4: 3 | C4: 45875 | D4: =_xlfn.CONCAT(A4,"_",B4) -> 4_3
A5: 4 | B5: 5 | C5: 45875 | D5: =_xlfn.CONCAT(A5,"_",B5) -> 4_5
A6: 4 | B6: 6 | C6: 45875 | D6: =_xlfn.CONCAT(A6,"_",B6) -> 4_6
A7: 4 | B7: 8 | C7: 45875 | D7: =_xlfn.CONCAT(A7,"_",B7) -> 4_8
A8: 4 | B8: 9 | C8: 45875 | D8: =_xlfn.CONCAT(A8,"_",B8) -> 4_9
A9: 4 | B9: 10 | C9: 45875 | D9: =_xlfn.CONCAT(A9,"_",B9) -> 4_10
A10: 4 | B10: 11 | C10: 45875 | D10: =_xlfn.CONCAT(A10,"_",B10) -> 4_11
A11: 5 | B11: 1 | C11: 45875 | D11: =_xlfn.CONCAT(A11,"_",B11) -> 5_1
A12: 5 | B12: 2 | C12: 45875 | D12: =_xlfn.CONCAT(A12,"_",B12) -> 5_2
A13: 5 | B13: 3 | C13: 45875 | D13: =_xlfn.CONCAT(A13,"_",B13) -> 5_3
... A118: 1 | B118: 33 | C118: 45894 | D118: =_xlfn.CONCAT(A118,"_",B118) -> 1_33
A119: 1-1 | B119: 21 | C119: 45894 | D119: =_xlfn.CONCAT(A119,"_",B119) -> 1-1_21
A120: 1-1 | B120: 34 | C120: 45894 | D120: =_xlfn.CONCAT(A120,"_",B120) -> 1-1_34
A121: 1-1 | B121: 35 | C121: 45894 | D121: =_xlfn.CONCAT(A121,"_",B121) -> 1-1_35
A122: 1-1 | B122: 38 | C122: 45894 | D122: =_xlfn.CONCAT(A122,"_",B122) -> 1-1_38
A123: 1-1 | B123: 39 | C123: 45894 | D123: =_xlfn.CONCAT(A123,"_",B123) -> 1-1_39
A124: 1-1 | B124: 40 | C124: 45894 | D124: =_xlfn.CONCAT(A124,"_",B124) -> 1-1_40
A125: 1-1 | B125: 41 | C125: 45894 | D125: =_xlfn.CONCAT(A125,"_",B125) -> 1-1_41
A126: 1-1 | B126: 42 | C126: 45894 | D126: =_xlfn.CONCAT(A126,"_",B126) -> 1-1_42
A127: 2 | B127: 1 | C127: 45894 | D127: =_xlfn.CONCAT(A127,"_",B127) -> 2_1
A128: 2 | B128: 2 | C128: 45894 | D128: =_xlfn.CONCAT(A128,"_",B128) -> 2_2
A129: 2 | B129: 3 | C129: 45894 | D129: =_xlfn.CONCAT(A129,"_",B129) -> 2_3
A130: 2 | B130: 4 | C130: 45894 | D130: =_xlfn.CONCAT(A130,"_",B130) -> 2_4
A131: 2 | B131: 5 | C131: 45894 | D131: =_xlfn.CONCAT(A131,"_",B131) -> 2_5
A132: 2 | B132: 6 | C132: 45894 | D132: =_xlfn.CONCAT(A132,"_",B132) -> 2_6
A133: 2 | B133: 19 | C133: 45894 | D133: =_xlfn.CONCAT(A133,"_",B133) -> 2_19
A134: 2 | B134: 20 | C134: 45894 | D134: =_xlfn.CONCAT(A134,"_",B134) -> 2_20
A135: 2 | B135: 21 | C135: 45894 | D135: =_xlfn.CONCAT(A135,"_",B135) -> 2_21
A136: 3 | B136: 9 | C136: 45894 | D136: =_xlfn.CONCAT(A136,"_",B136) -> 3_9
A137: 3 | B137: 11 | C137: 45894 | D137: =_xlfn.CONCAT(A137,"_",B137) -> 3_11
A138: 3 | B138: 13 | C138: 45894 | D138: =_xlfn.CONCAT(A138,"_",B138) -> 3_13
... A315: 1 | B315: 11 | C315: 45894 | D315: =_xlfn.CONCAT(A315,"_",B315) -> 1_11
A316: 20 | B316: 1 | C316: 45983 | D316: =_xlfn.CONCAT(A316,"_",B316) -> 20_1 | E316: 45984 | F316: =_xlfn.CONCAT(A316,"_",B316) -> 20_1
A317: 20 | B317: 8 | C317: 45983 | D317: =_xlfn.CONCAT(A317,"_",B317) -> 20_8 | E317: 45984 | F317: =_xlfn.CONCAT(A317,"_",B317) -> 20_8
A318: 19 | B318: 1 | C318: 45983 | D318: =_xlfn.CONCAT(A318,"_",B318) -> 19_1 | E318: 45984 | F318: =_xlfn.CONCAT(A318,"_",B318) -> 19_1
A319: 16 | B319: 3 | C319: 45983 | D319: =_xlfn.CONCAT(A319,"_",B319) -> 16_3 | E319: 45984 | F319: =_xlfn.CONCAT(A319,"_",B319) -> 16_3
A320: 17 | B320: 22 | C320: 45983 | D320: =_xlfn.CONCAT(A320,"_",B320) -> 17_22 | E320: 45984 | F320: =_xlfn.CONCAT(A320,"_",B320) -> 17_22
...

Sheet 現場PE包覆數量
A1: 序列 | B1: 尺寸 | C1: 數量 | D1: 日期 | E1: 請款月份
A2: 1 | B2: 8 | C2: 7 | D2: 45979 | E2: 11月
A3: 2 | B3: 6 | C3: 22 | D3: 45979 | E3: 11月
A4: 3 | B4: 4 | C4: 17 | D4: 45979 | E4: 11月
A5: 4 | B5: 2.5 | C5: 1 | D5: 45979 | E5: 11月
A6: 5 | B6: 6 | C6: 11 | D6: 46013 | E6: 12月
A7: 6 | B7: 4 | C7: 30 | D7: 46013 | E7: 12月
A8: 7 | B8: 3 | C8: 2 | D8: 46013 | E8: 12月
A9: 8 | B9: 2.5 | C9: 1 | D9: 46013 | E9: 12月
A10: 9 | B10: 2 | C10: 1 | D10: 46013 | E10: 12月

Sheet PE包覆分析
A1: RT.PT檢驗日期 | B1: (多重項目)
A3: 尺寸 | B3: 加總 - 計數
A4: 6 | B4: 11
A5: 4 | B5: 30
A6: 3 | B6: 2
A7: 2.5 | B7: 1
A8: 2 | B8: 1
